defmodule WebsockexNew.ErrorIntegrationTest do
  use ExUnit.Case, async: false

  alias WebsockexNew.Client
  alias WebsockexNew.ErrorHandler
  alias WebsockexNew.Examples.DeribitAdapter

  @moduletag :integration

  @test_ws_url "wss://test.deribit.com/ws/api/v2"
  @invalid_url "wss://invalid-domain-that-does-not-exist.com/ws"

  describe "connection errors" do
    test "handles invalid domain gracefully" do
      assert {:error, reason} = Client.connect(@invalid_url)

      {category, _} = ErrorHandler.categorize_error(reason)
      assert category in [:connection_error, :timeout_error]

      # Test that we can at least handle the error properly
      result = ErrorHandler.handle_error(reason)
      assert result == :reconnect
      assert ErrorHandler.recoverable?(reason)
    end

    test "handles connection timeout" do
      # Use a very short timeout to force timeout error
      config = WebsockexNew.Config.new!(@test_ws_url, timeout: 1)

      assert {:error, reason} = Client.connect(config)

      case reason do
        {:error, :timeout} ->
          assert ErrorHandler.recoverable?(reason)
          assert ErrorHandler.handle_error(reason) == :reconnect

        :timeout ->
          assert ErrorHandler.recoverable?(reason)
          assert ErrorHandler.handle_error(reason) == :reconnect

        _ ->
          # Connection might succeed faster than 1ms, which is fine
          :ok
      end
    end

    test "reconnect function handles errors properly" do
      {:ok, client} = Client.connect(@test_ws_url)

      # Close the connection first
      :ok = Client.close(client)

      # Now try to reconnect - this should work
      case Client.reconnect(client) do
        {:ok, _new_client} ->
          :ok

        {:error, {:recoverable, _reason}} ->
          :ok

        {:error, reason} ->
          # Some errors might not be recoverable in test environment
          refute ErrorHandler.recoverable?(reason)
      end
    end
  end

  describe "authentication errors with Deribit" do
    test "handles invalid credentials gracefully" do
      {:ok, client} = Client.connect(@test_ws_url)

      # Send invalid authentication request
      invalid_auth_message =
        Jason.encode!(%{
          jsonrpc: "2.0",
          id: 1,
          method: "public/auth",
          params: %{
            grant_type: "client_credentials",
            client_id: "invalid_client_id",
            client_secret: "invalid_secret"
          }
        })

      assert :ok = Client.send_message(client, invalid_auth_message)

      # We can't easily test the error response in this simple test,
      # but we've verified the message sending mechanism works

      Client.close(client)
    end

    test "DeribitAdapter handles API errors" do
      error_response = %{
        "jsonrpc" => "2.0",
        "id" => 1,
        "error" => %{
          "code" => -32_602,
          "message" => "invalid_credentials"
        }
      }

      # This tests our error handling logic without needing network calls
      result = DeribitAdapter.handle_message({:text, Jason.encode!(error_response)})
      assert result == :ok
    end
  end

  describe "protocol errors" do
    test "handles malformed JSON gracefully" do
      {:ok, client} = Client.connect(@test_ws_url)

      # Send invalid JSON - this will test protocol error handling
      invalid_json = "{ invalid json structure"

      # Note: Gun might reject this at the protocol level before it reaches our handler
      case Client.send_message(client, invalid_json) do
        :ok -> :ok
        # Expected for malformed data
        {:error, _reason} -> :ok
      end

      Client.close(client)
    end

    test "ErrorHandler categorizes frame errors correctly" do
      frame_error = {:error, {:bad_frame, :invalid_opcode}}

      assert {:protocol_error, ^frame_error} = ErrorHandler.categorize_error(frame_error)
      assert ErrorHandler.handle_error(frame_error) == :stop
      refute ErrorHandler.recoverable?(frame_error)
    end
  end

  describe "error recovery patterns" do
    test "connection errors are marked as recoverable" do
      connection_errors = [
        {:error, :econnrefused},
        {:error, :timeout},
        {:error, :nxdomain},
        {:gun_down, self(), :http, :closed, []},
        {:gun_error, self(), make_ref(), :timeout}
      ]

      for error <- connection_errors do
        assert ErrorHandler.recoverable?(error), "Expected #{inspect(error)} to be recoverable"
        assert ErrorHandler.handle_error(error) == :reconnect
      end
    end

    test "protocol and auth errors are not recoverable" do
      non_recoverable_errors = [
        {:error, :invalid_frame},
        {:error, :unauthorized},
        {:error, :invalid_credentials},
        {:error, {:bad_frame, :invalid_opcode}}
      ]

      for error <- non_recoverable_errors do
        refute ErrorHandler.recoverable?(error), "Expected #{inspect(error)} to not be recoverable"
        assert ErrorHandler.handle_error(error) == :stop
      end
    end
  end
end
